Workbook
Name ___DAT10: #REF!
Name ___DAT11: #REF!
Name ___DAT12: #REF!
Name ___DAT13: #REF!
Name ___DAT14: #REF!
Name ___DAT15: #REF!
Name ___DAT16: #REF!
Name ___DAT17: #REF!
Name ___DAT18: #REF!
Name ___DAT19: #REF!
Name ___DAT2: #REF!
Name ___DAT20: #REF!
Name ___DAT21: #REF!
Name ___DAT22: #REF!
Name ___DAT23: #REF!
Name ___DAT24: #REF!
Name ___DAT25: #REF!
Name ___DAT3: #REF!
Name ___DAT4: #REF!
Name ___DAT5: #REF!
Name ___DAT6: #REF!
Name ___DAT7: #REF!
Name ___DAT8: #REF!
Name ___DAT9: #REF!
Name __DAT1: #REF!
Name __DAT10: #REF!
Name __DAT11: #REF!
Name __DAT12: #REF!
Name __DAT13: #REF!
Name __DAT14: #REF!
Name __DAT15: #REF!
Name __DAT16: #REF!
Name __DAT17: #REF!
Name __DAT18: #REF!
Name __DAT19: #REF!
Name __DAT2: #REF!
Name __DAT20: #REF!
Name __DAT21: #REF!
Name __DAT22: #REF!
Name __DAT23: #REF!
Name __DAT24: #REF!
Name __DAT25: #REF!
Name __DAT3: #REF!
Name __DAT4: #REF!
Name __DAT5: #REF!
Name __DAT6: #REF!
Name __DAT7: #REF!
Name __DAT8: #REF!
Name __DAT9: #REF!
Name _DAT1: #REF!
Name _DAT10: #REF!
Name _DAT11: #REF!
Name _DAT12: #REF!
Name _DAT13: #REF!
Name _DAT14: #REF!
Name _DAT15: #REF!
Name _DAT16: #REF!
Name _DAT17: #REF!
Name _DAT18: #REF!
Name _DAT19: #REF!

Sheet BS-Liabilities
A1: Liabilities | B1: Main Category | C1: Sub Category | D1: Particulars | E1: Item Number | F1: 46174 | G1: 46082 | H1: Variance | I1: Reasons | K1: 45901 | L1: 45992
A2: Current liabilities ( ≤ 1 year) | B2: Trade payables | C2: Trade payables | D2: Trade payables - 3rd, B-c, B-f | E2: 20100 | F2: =IFERROR(VLOOKUP(E2,'[9]SAP Input-BS'!$A$5:$F$502,5,0),0) -> -6.5071733e+09 | G2: =IFERROR(VLOOKUP(E2,'[10]SAP Input-BS'!$A$5:$F$500,5,0),0) -> -5.0483844e+09 | H2: =F2-G2 -> -1.4587889e+09 | J2: Schedule | K2: =IFERROR(VLOOKUP(E2,'[11]SAP Input-BS'!$A$5:$E$500,5,0),0) -> -6.3165899e+09 | L2: -7.9635468e+09
A3: Current liabilities ( ≤ 1 year) | B3: Trade payables | C3: Trade payables | D3: Trade payables - K | E3: 20120 | F3: =IFERROR(VLOOKUP(E3,'[9]SAP Input-BS'!$A$5:$F$502,5,0),0) -> -4830249126 | G3: =IFERROR(VLOOKUP(E3,'[10]SAP Input-BS'!$A$5:$F$500,5,0),0) -> -4.0158494e+09 | H3: =F3-G3 -> -8.143997e+08 | K3: =IFERROR(VLOOKUP(E3,'[11]SAP Input-BS'!$A$5:$E$500,5,0),0) -> -2.9790446e+09 | L3: -4.2969963e+09
A4: Current liabilities ( ≤ 1 year) | B4: Trade payables | C4: Trade payables | D4: License payables - K | E4: 20125 | F4: =IFERROR(VLOOKUP(E4,'[9]SAP Input-BS'!$A$5:$F$502,5,0),0) -> -28893230 | G4: =IFERROR(VLOOKUP(E4,'[10]SAP Input-BS'!$A$5:$F$500,5,0),0) -> -8508157.9 | H4: =F4-G4 -> -20385072 | K4: =IFERROR(VLOOKUP(E4,'[11]SAP Input-BS'!$A$5:$E$500,5,0),0) -> -1.2881517e+08 | L4: -2.3793154e+08
A5: Current liabilities ( ≤ 1 year) | B5: Trade payables | C5: Trade payables | D5: Trade payables - N | E5: 20140 | F5: =IFERROR(VLOOKUP(E5,'[9]SAP Input-BS'!$A$5:$F$502,5,0),0) -> -44746309 | G5: =IFERROR(VLOOKUP(E5,'[10]SAP Input-BS'!$A$5:$F$500,5,0),0) -> -44746308 | H5: =F5-G5 -> -0.71 | J5: Schedule | K5: =IFERROR(VLOOKUP(E5,'[11]SAP Input-BS'!$A$5:$E$500,5,0),0) -> 0 | L5: -44746309
A6: Current liabilities ( ≤ 1 year) | B6: Trade payables | C6: Trade payables | D6: Trade payables - B-a | E6: 20160 | F6: =IFERROR(VLOOKUP(E6,'[9]SAP Input-BS'!$A$5:$F$502,5,0),0) -> 0 | G6: =IFERROR(VLOOKUP(E6,'[10]SAP Input-BS'!$A$5:$F$500,5,0),0) -> 0 | H6: =F6-G6 -> 0 | K6: =IFERROR(VLOOKUP(E6,'[11]SAP Input-BS'!$A$5:$E$500,5,0),0) -> 0 | L6: 0
A7: Current liabilities ( ≤ 1 year) | B7: Trade payables | C7: Trade payables | D7: Total: Trade payables | E7: 20179 | F7: =IFERROR(VLOOKUP(E7,'[9]SAP Input-BS'!$A$5:$F$502,5,0),0) -> -1.1243962e+10 | G7: =IFERROR(VLOOKUP(E7,'[10]SAP Input-BS'!$A$5:$F$500,5,0),0) -> -9.1174883e+09 | H7: =F7-G7 -> -2.1264736e+09 | K7: =IFERROR(VLOOKUP(E7,'[11]SAP Input-BS'!$A$5:$E$500,5,0),0) -> -9.4244496e+09 | L7: -1.2543221e+10
A8: Current liabilities ( ≤ 1 year) | B8: Trade payables | C8: Trade payables | D8: Notes payable | E8: 20180 | F8: =IFERROR(VLOOKUP(E8,'[9]SAP Input-BS'!$A$5:$F$502,5,0),0) -> 0 | G8: =IFERROR(VLOOKUP(E8,'[10]SAP Input-BS'!$A$5:$F$500,5,0),0) -> 0 | H8: =F8-G8 -> 0 | K8: =IFERROR(VLOOKUP(E8,'[11]SAP Input-BS'!$A$5:$E$500,5,0),0) -> 0 | L8: 0
A9: Current liabilities ( ≤ 1 year) | B9: Trade payables | C9: Trade payables | D9: Total: Trade payables and notes payable | E9: LC_AP | F9: =IFERROR(VLOOKUP(E9,'[9]SAP Input-BS'!$A$5:$F$502,5,0),0) -> -1.1411062e+10 | G9: =IFERROR(VLOOKUP(E9,'[10]SAP Input-BS'!$A$5:$F$500,5,0),0) -> -9.1174883e+09 | H9: =F9-G9 -> -2.2935737e+09 | K9: =IFERROR(VLOOKUP(E9,'[11]SAP Input-BS'!$A$5:$E$500,5,0),0) -> -9.4244496e+09 | L9: -1.2543221e+10
A10: Current liabilities ( ≤ 1 year) | B10: Lease liabilities (lessee) ≤ 1 y | C10: Lease liabilities (lessee) ≤ 1 y | D10: Lease liabilities (lessee) ≤ 1 y | E10: 21500 | F10: =IFERROR(VLOOKUP(E10,'[9]SAP Input-BS'!$A$5:$F$502,5,0),0) -> -1.7554863e+09 | G10: =IFERROR(VLOOKUP(E10,'[10]SAP Input-BS'!$A$5:$F$500,5,0),0) -> -2.6661777e+09 | H10: =F10-G10 -> 9.1069146e+08 | K10: =IFERROR(VLOOKUP(E10,'[11]SAP Input-BS'!$A$5:$E$500,5,0),0) -> -1.1066156e+09 | L10: -2.2974229e+09
A11: Current liabilities ( ≤ 1 year) | B11: Lease liabilities (lessee) ≤ 1 y | C11: Lease liabilities (lessee) ≤ 1 y | D11: Total: Lease liabilities (lessee) ≤ 1 y | E11: LC_LL | F11: =IFERROR(VLOOKUP(E11,'[9]SAP Input-BS'!$A$5:$F$502,5,0),0) -> -1.7554863e+09 | G11: =IFERROR(VLOOKUP(E11,'[10]SAP Input-BS'!$A$5:$F$500,5,0),0) -> -2.6661777e+09 | H11: =F11-G11 -> 9.1069146e+08 | K11: =IFERROR(VLOOKUP(E11,'[11]SAP Input-BS'!$A$5:$E$500,5,0),0) -> -1.1066156e+09 | L11: -2.2974229e+09
A12: Current liabilities ( ≤ 1 year) | B12: Financial liabilities | D12: Bonds ≤ 1 y | E12: 20010 | F12: =IFERROR(VLOOKUP(E12,'[9]SAP Input-BS'!$A$5:$F$502,5,0),0) -> 0 | G12: =IFERROR(VLOOKUP(E12,'[10]SAP Input-BS'!$A$5:$F$500,5,0),0) -> 0 | H12: =F12-G12 -> 0 | K12: =IFERROR(VLOOKUP(E12,'[11]SAP Input-BS'!$A$5:$E$500,5,0),0) -> 0 | L12: 0
A13: Current liabilities ( ≤ 1 year) | B13: Financial liabilities | D13: Liabilities with banks ≤ 1 y | E13: 20020 | F13: =IFERROR(VLOOKUP(E13,'[9]SAP Input-BS'!$A$5:$F$502,5,0),0) -> 0 | G13: =IFERROR(VLOOKUP(E13,'[10]SAP Input-BS'!$A$5:$F$500,5,0),0) -> 0 | H13: =F13-G13 -> 0 | K13: =IFERROR(VLOOKUP(E13,'[11]SAP Input-BS'!$A$5:$E$500,5,0),0) -> 0 | L13: 0
A14: Current liabilities ( ≤ 1 year) | B14: Financial liabilities | D14: Commercial papers ≤ 1 y | E14: 20030 | F14: =IFERROR(VLOOKUP(E14,'[9]SAP Input-BS'!$A$5:$F$502,5,0),0) -> 0 | G14: =IFERROR(VLOOKUP(E14,'[10]SAP Input-BS'!$A$5:$F$500,5,0),0) -> 0 | H14: =F14-G14 -> 0 | K14: =IFERROR(VLOOKUP(E14,'[11]SAP Input-BS'!$A$5:$E$500,5,0),0) -> 0 | L14: 0
A15: Current liabilities ( ≤ 1 year) | B15: Financial liabilities | D15: Promissory note loans ≤ 1 y | E15: 20035 | F15: =IFERROR(VLOOKUP(E15,'[9]SAP Input-BS'!$A$5:$F$502,5,0),0) -> 0 | G15: =IFERROR(VLOOKUP(E15,'[10]SAP Input-BS'!$A$5:$F$500,5,0),0) -> 0 | H15: =F15-G15 -> 0 | K15: =IFERROR(VLOOKUP(E15,'[11]SAP Input-BS'!$A$5:$E$500,5,0),0) -> 0 | L15: 0
A16: Current liabilities ( ≤ 1 year) | B16: Financial liabilities | D16: Other financial liabilities ≤ 1 y | E16: 20040 | F16: =IFERROR(VLOOKUP(E16,'[9]SAP Input-BS'!$A$5:$F$502,5,0),0) -> 0 | G16: =IFERROR(VLOOKUP(E16,'[10]SAP Input-BS'!$A$5:$F$500,5,0),0) -> 0 | H16: =F16-G16 -> 0 | K16: =IFERROR(VLOOKUP(E16,'[11]SAP Input-BS'!$A$5:$E$500,5,0),0) -> 0 | L16: 0
A17: Current liabilities ( ≤ 1 year) | B17: Financial liabilities | D17: Total: Financial liabilities ≤ 1 y | E17: 20099 | F17: =IFERROR(VLOOKUP(E17,'[9]SAP Input-BS'!$A$5:$F$502,5,0),0) -> 0 | G17: =IFERROR(VLOOKUP(E17,'[10]SAP Input-BS'!$A$5:$F$500,5,0),0) -> 0 | H17: =F17-G17 -> 0 | K17: =IFERROR(VLOOKUP(E17,'[11]SAP Input-BS'!$A$5:$E$500,5,0),0) -> 0 | L17: 0
A18: Current liabilities ( ≤ 1 year) | B18: Loans ≤ 1 y | D18: Loans ≤ 1 y - 3rd, B-c, B-f | E18: 20300 | F18: =IFERROR(VLOOKUP(E18,'[9]SAP Input-BS'!$A$5:$F$502,5,0),0) -> 0 | G18: =IFERROR(VLOOKUP(E18,'[10]SAP Input-BS'!$A$5:$F$500,5,0),0) -> 0 | H18: =F18-G18 -> 0 | K18: =IFERROR(VLOOKUP(E18,'[11]SAP Input-BS'!$A$5:$E$500,5,0),0) -> 0 | L18: 0
A19: Current liabilities ( ≤ 1 year) | B19: Loans ≤ 1 y | D19: Loans ≤ 1 y - K | E19: 20320 | F19: =IFERROR(VLOOKUP(E19,'[9]SAP Input-BS'!$A$5:$F$502,5,0),0) -> 0 | G19: =IFERROR(VLOOKUP(E19,'[10]SAP Input-BS'!$A$5:$F$500,5,0),0) -> 0 | H19: =F19-G19 -> 0 | K19: =IFERROR(VLOOKUP(E19,'[11]SAP Input-BS'!$A$5:$E$500,5,0),0) -> 0 | L19: 0
A20: Current liabilities ( ≤ 1 year) | B20: Loans ≤ 1 y | D20: Loans ≤ 1 y - N | E20: 20340 | F20: =IFERROR(VLOOKUP(E20,'[9]SAP Input-BS'!$A$5:$F$502,5,0),0) -> 0 | G20: =IFERROR(VLOOKUP(E20,'[10]SAP Input-BS'!$A$5:$F$500,5,0),0) -> 0 | H20: =F20-G20 -> 0 | K20: =IFERROR(VLOOKUP(E20,'[11]SAP Input-BS'!$A$5:$E$500,5,0),0) -> 0 | L20: 0
A21: Current liabilities ( ≤ 1 year) | B21: Loans ≤ 1 y | D21: Loans ≤ 1 y - B-a | E21: 20360 | F21: =IFERROR(VLOOKUP(E21,'[9]SAP Input-BS'!$A$5:$F$502,5,0),0) -> 0 | G21: =IFERROR(VLOOKUP(E21,'[10]SAP Input-BS'!$A$5:$F$500,5,0),0) -> 0 | H21: =F21-G21 -> 0 | K21: =IFERROR(VLOOKUP(E21,'[11]SAP Input-BS'!$A$5:$E$500,5,0),0) -> 0 | L21: 0
A22: Current liabilities ( ≤ 1 year) | B22: Loans ≤ 1 y | D22: Total: Loans ≤ 1 y | E22: 20379 | F22: =IFERROR(VLOOKUP(E22,'[9]SAP Input-BS'!$A$5:$F$502,5,0),0) -> 0 | G22: =IFERROR(VLOOKUP(E22,'[10]SAP Input-BS'!$A$5:$F$500,5,0),0) -> 0 | H22: =F22-G22 -> 0 | K22: =IFERROR(VLOOKUP(E22,'[11]SAP Input-BS'!$A$5:$E$500,5,0),0) -> 0 | L22: 0
A23: Current liabilities ( ≤ 1 year) | B23: Financial clearing, cash pool | C23: Financial clearing, cash pool | D23: Financial clearing, cash pool - K | E23: 20420 | F23: =IFERROR(VLOOKUP(E23,'[9]SAP Input-BS'!$A$5:$F$502,5,0),0) -> 0 | G23: =IFERROR(VLOOKUP(E23,'[10]SAP Input-BS'!$A$5:$F$500,5,0),0) -> 0 | H23: =F23-G23 -> 0 | K23: =IFERROR(VLOOKUP(E23,'[11]SAP Input-BS'!$A$5:$E$500,5,0),0) -> 0 | L23: 0
A24: Current liabilities ( ≤ 1 year) | B24: Financial clearing, cash pool | C24: Financial clearing, cash pool | D24: Financial clearing, cash pool - N | E24: 20440 | F24: =IFERROR(VLOOKUP(E24,'[9]SAP Input-BS'!$A$5:$F$502,5,0),0) -> 0 | G24: =IFERROR(VLOOKUP(E24,'[10]SAP Input-BS'!$A$5:$F$500,5,0),0) -> 0 | H24: =F24-G24 -> 0 | K24: =IFERROR(VLOOKUP(E24,'[11]SAP Input-BS'!$A$5:$E$500,5,0),0) -> 0 | L24: 0
A25: Current liabilities ( ≤ 1 year) | B25: Financial clearing, cash pool | C25: Financial clearing, cash pool | D25: Financial clearing, cash pool - B-a | E25: 20460 | F25: =IFERROR(VLOOKUP(E25,'[9]SAP Input-BS'!$A$5:$F$502,5,0),0) -> 0 | G25: =IFERROR(VLOOKUP(E25,'[10]SAP Input-BS'!$A$5:$F$500,5,0),0) -> 0 | H25: =F25-G25 -> 0 | K25: =IFERROR(VLOOKUP(E25,'[11]SAP Input-BS'!$A$5:$E$500,5,0),0) -> 0 | L25: 0
A26: Current liabilities ( ≤ 1 year) | B26: Financial clearing, cash pool | C26: Financial clearing, cash pool | D26: Financial clearing, cash pool - B-c, B-f | E26: 20470 | F26: =IFERROR(VLOOKUP(E26,'[9]SAP Input-BS'!$A$5:$F$502,5,0),0) -> 0 | G26: =IFERROR(VLOOKUP(E26,'[10]SAP Input-BS'!$A$5:$F$500,5,0),0) -> 0 | H26: =F26-G26 -> 0 | K26: =IFERROR(VLOOKUP(E26,'[11]SAP Input-BS'!$A$5:$E$500,5,0),0) -> 0 | L26: 0
A27: Current liabilities ( ≤ 1 year) | B27: Financial clearing, cash pool | C27: Financial clearing, cash pool | D27: Total: Financial clearing, cash pool | E27: 20479 | F27: =IFERROR(VLOOKUP(E27,'[9]SAP Input-BS'!$A$5:$F$502,5,0),0) -> 0 | G27: =IFERROR(VLOOKUP(E27,'[10]SAP Input-BS'!$A$5:$F$500,5,0),0) -> 0 | H27: =F27-G27 -> 0 | K27: =IFERROR(VLOOKUP(E27,'[11]SAP Input-BS'!$A$5:$E$500,5,0),0) -> 0 | L27: 0
A28: Current liabilities ( ≤ 1 year) | B28: Financial liabilities ≤ 1 y | C28: Derivatives Outstanding | D28: Derivatives w/o hedge ≤ 1 y - 3rd | E28: 21305 | F28: =IFERROR(VLOOKUP(E28,'[9]SAP Input-BS'!$A$5:$F$502,5,0),0) -> -4.6308147e+08 | G28: =IFERROR(VLOOKUP(E28,'[10]SAP Input-BS'!$A$5:$F$500,5,0),0) -> -1425368884 | H28: =F28-G28 -> 9.6228741e+08 | J28: =(F28-G28)/87 -> 11060775 | K28: =IFERROR(VLOOKUP(E28,'[11]SAP Input-BS'!$A$5:$E$500,5,0),0) -> -7.3916284e+08 | L28: -5.6610601e+08
A29: Current liabilities ( ≤ 1 year) | B29: Financial liabilities ≤ 1 y | D29: Liabilities dividends - 3rd, B-c, B-f | E29: 21312 | F29: =IFERROR(VLOOKUP(E29,'[9]SAP Input-BS'!$A$5:$F$502,5,0),0) -> 0 | G29: =IFERROR(VLOOKUP(E29,'[10]SAP Input-BS'!$A$5:$F$500,5,0),0) -> 0 | H29: =F29-G29 -> 0 | K29: =IFERROR(VLOOKUP(E29,'[11]SAP Input-BS'!$A$5:$E$500,5,0),0) -> 0 | L29: 0
A30: Current liabilities ( ≤ 1 year) | B30: Financial liabilities ≤ 1 y | D30: Debtors with credit balances - 3rd, B-c, B-f | E30: 21314 | F30: =IFERROR(VLOOKUP(E30,'[9]SAP Input-BS'!$A$5:$F$502,5,0),0) -> 0 | G30: =IFERROR(VLOOKUP(E30,'[10]SAP Input-BS'!$A$5:$F$500,5,0),0) -> 0 | H30: =F30-G30 -> 0 | K30: =IFERROR(VLOOKUP(E30,'[11]SAP Input-BS'!$A$5:$E$500,5,0),0) -> 0 | L30: 0
A31: Current liabilities ( ≤ 1 year) | B31: Financial liabilities ≤ 1 y | D31: Liabilities accrued interest - 3rd, B-c, B-f | E31: 21315 | F31: =IFERROR(VLOOKUP(E31,'[9]SAP Input-BS'!$A$5:$F$502,5,0),0) -> 0 | G31: =IFERROR(VLOOKUP(E31,'[10]SAP Input-BS'!$A$5:$F$500,5,0),0) -> 0 | H31: =F31-G31 -> 0 | K31: =IFERROR(VLOOKUP(E31,'[11]SAP Input-BS'!$A$5:$E$500,5,0),0) -> 0 | L31: 0
A32: Current liabilities ( ≤ 1 year) | B32: Financial liabilities ≤ 1 y | C32: Withheld and Retention amount & Capital Creditors reclass | D32: Other financial liabilities ≤ 1 y - 3rd, B-c, B-f | E32: 21318 | F32: =IFERROR(VLOOKUP(E32,'[9]SAP Input-BS'!$A$5:$F$502,5,0),0) -> -8.7410343e+08 | G32: =IFERROR(VLOOKUP(E32,'[10]SAP Input-BS'!$A$5:$F$500,5,0),0) -> -4.1923078e+08 | H32: =F32-G32 -> -4.5487265e+08 | K32: =IFERROR(VLOOKUP(E32,'[11]SAP Input-BS'!$A$5:$E$500,5,0),0) -> -1.4897683e+08 | L32: -1.2064413e+09
A33: Current liabilities ( ≤ 1 year) | B33: Financial liabilities ≤ 1 y | D33: Liabilities PTA/dividends - K | E33: 21321 | F33: =IFERROR(VLOOKUP(E33,'[9]SAP Input-BS'!$A$5:$F$502,5,0),0) -> 0 | G33: =IFERROR(VLOOKUP(E33,'[10]SAP Input-BS'!$A$5:$F$500,5,0),0) -> 0 | H33: =F33-G33 -> 0 | K33: =IFERROR(VLOOKUP(E33,'[11]SAP Input-BS'!$A$5:$E$500,5,0),0) -> 0 | L33: 0
A34: Current liabilities ( ≤ 1 year) | B34: Financial liabilities ≤ 1 y | C34: Debtors with Credit balance | D34: Debtors with credit balances - K | E34: 21324 | F34: =IFERROR(VLOOKUP(E34,'[9]SAP Input-BS'!$A$5:$F$502,5,0),0) -> -13800179 | G34: =IFERROR(VLOOKUP(E34,'[10]SAP Input-BS'!$A$5:$F$500,5,0),0) -> -29669370 | H34: =F34-G34 -> 15869191 | K34: =IFERROR(VLOOKUP(E34,'[11]SAP Input-BS'!$A$5:$E$500,5,0),0) -> -37223401 | L34: -8816775.8
A35: Current liabilities ( ≤ 1 year) | B35: Financial liabilities ≤ 1 y | D35: Liabilities accrued interest - K | E35: 21325 | F35: =IFERROR(VLOOKUP(E35,'[9]SAP Input-BS'!$A$5:$F$502,5,0),0) -> 0 | G35: =IFERROR(VLOOKUP(E35,'[10]SAP Input-BS'!$A$5:$F$500,5,0),0) -> 0 | H35: =F35-G35 -> 0 | K35: =IFERROR(VLOOKUP(E35,'[11]SAP Input-BS'!$A$5:$E$500,5,0),0) -> 0 | L35: 0
A36: Current liabilities ( ≤ 1 year) | B36: Financial liabilities ≤ 1 y | D36: Other financial liabilities ≤ 1 y - K | E36: 21328 | F36: =IFERROR(VLOOKUP(E36,'[9]SAP Input-BS'!$A$5:$F$502,5,0),0) -> -17855875 | G36: =IFERROR(VLOOKUP(E36,'[10]SAP Input-BS'!$A$5:$F$500,5,0),0) -> 0 | H36: =F36-G36 -> -17855875 | K36: =IFERROR(VLOOKUP(E36,'[11]SAP Input-BS'!$A$5:$E$500,5,0),0) -> 0 | L36: 0
A37: Current liabilities ( ≤ 1 year) | B37: Financial liabilities ≤ 1 y | D37: Liabilities PTA/dividends - N | E37: 21341 | F37: =IFERROR(VLOOKUP(E37,'[9]SAP Input-BS'!$A$5:$F$502,5,0),0) -> 0 | G37: =IFERROR(VLOOKUP(E37,'[10]SAP Input-BS'!$A$5:$F$500,5,0),0) -> 0 | H37: =F37-G37 -> 0 | K37: =IFERROR(VLOOKUP(E37,'[11]SAP Input-BS'!$A$5:$E$500,5,0),0) -> 0 | L37: 0
A38: Current liabilities ( ≤ 1 year) | B38: Financial liabilities ≤ 1 y | D38: Debtors with credit balances - N | E38: 21344 | F38: =IFERROR(VLOOKUP(E38,'[9]SAP Input-BS'!$A$5:$F$502,5,0),0) -> 0 | G38: =IFERROR(VLOOKUP(E38,'[10]SAP Input-BS'!$A$5:$F$500,5,0),0) -> 0 | H38: =F38-G38 -> 0 | K38: =IFERROR(VLOOKUP(E38,'[11]SAP Input-BS'!$A$5:$E$500,5,0),0) -> 0 | L38: 0
A39: Current liabilities ( ≤ 1 year) | B39: Financial liabilities ≤ 1 y | D39: Liabilities accrued interest - N | E39: 21345 | F39: =IFERROR(VLOOKUP(E39,'[9]SAP Input-BS'!$A$5:$F$502,5,0),0) -> 0 | G39: =IFERROR(VLOOKUP(E39,'[10]SAP Input-BS'!$A$5:$F$500,5,0),0) -> 0 | H39: =F39-G39 -> 0 | K39: =IFERROR(VLOOKUP(E39,'[11]SAP Input-BS'!$A$5:$E$500,5,0),0) -> 0 | L39: 0
A40: Current liabilities ( ≤ 1 year) | B40: Financial liabilities ≤ 1 y | D40: Other financial liabilities ≤ 1 y - N | E40: 21348 | F40: =IFERROR(VLOOKUP(E40,'[9]SAP Input-BS'!$A$5:$F$502,5,0),0) -> 0 | G40: =IFERROR(VLOOKUP(E40,'[10]SAP Input-BS'!$A$5:$F$500,5,0),0) -> 0 | H40: =F40-G40 -> 0 | K40: =IFERROR(VLOOKUP(E40,'[11]SAP Input-BS'!$A$5:$E$500,5,0),0) -> 0 | L40: 0
...

Sheet BS-Assets
A1: Assets | B1: Main Category | C1: Sub Category | D1: Particulars | E1: Item Number | F1: 46174 | G1: 46082 | H1: Variance | I1: Reasons | K1: 45901 | L1: 45992
A2: Current Assets | B2: Cash and cash equivalents | C2: Cash and cash equivalents | D2: Cheques | E2: 17001 | F2: =IFERROR(VLOOKUP(E2,'[9]SAP Input-BS'!$A$5:$F$502,5,0),0) -> 0 | G2: =IFERROR(VLOOKUP(E2,'[10]SAP Input-BS'!$A$5:$F$500,5,0),0) -> 0 | H2: =F2-G2 -> 0 | K2: =IFERROR(VLOOKUP(E2,'[11]SAP Input-BS'!$A$5:$E$500,5,0),0) -> 0 | L2: 0
A3: Current Assets | B3: Cash and cash equivalents | C3: Cash and cash equivalents | D3: Cash on hand | E3: 17003 | F3: =IFERROR(VLOOKUP(E3,'[9]SAP Input-BS'!$A$5:$F$502,5,0),0) -> 13 | G3: =IFERROR(VLOOKUP(E3,'[10]SAP Input-BS'!$A$5:$F$500,5,0),0) -> 1234 | H3: =F3-G3 -> -1221 | K3: =IFERROR(VLOOKUP(E3,'[11]SAP Input-BS'!$A$5:$E$500,5,0),0) -> 2415 | L3: 2301
A4: Current Assets | B4: Cash and cash equivalents | C4: Cash and cash equivalents | D4: Bank balances ≤ 90 days | E4: 17005 | F4: =IFERROR(VLOOKUP(E4,'[9]SAP Input-BS'!$A$5:$F$502,5,0),0) -> 1.2020967e+10 | G4: =IFERROR(VLOOKUP(E4,'[10]SAP Input-BS'!$A$5:$F$500,5,0),0) -> 1560768050 | H4: =F4-G4 -> 1.0460199e+10 | K4: =IFERROR(VLOOKUP(E4,'[11]SAP Input-BS'!$A$5:$E$500,5,0),0) -> 4.0931609e+09 | L4: 7.5445585e+09
A5: Current Assets | B5: Cash and cash equivalents | C5: Cash and cash equivalents | D5: Total: Cash and cash equivalents | E5: AC_CH | F5: =IFERROR(VLOOKUP(E5,'[9]SAP Input-BS'!$A$5:$F$502,5,0),0) -> 1.2020967e+10 | G5: =IFERROR(VLOOKUP(E5,'[10]SAP Input-BS'!$A$5:$F$500,5,0),0) -> 1560769284 | H5: =F5-G5 -> 1.0460198e+10 | K5: =IFERROR(VLOOKUP(E5,'[11]SAP Input-BS'!$A$5:$E$500,5,0),0) -> 4.0931633e+09 | L5: 7.5445608e+09
A6: Current Assets | B6: Trade receivables | C6: Trade receivables | D6: Trade receivables - 3rd, B-c, B-f | E6: 18000 | F6: =IFERROR(VLOOKUP(E6,'[9]SAP Input-BS'!$A$5:$F$502,5,0),0) -> 1.671417e+09 | G6: =IFERROR(VLOOKUP(E6,'[10]SAP Input-BS'!$A$5:$F$500,5,0),0) -> 2.1105355e+09 | H6: =F6-G6 -> -4.3911846e+08 | K6: =IFERROR(VLOOKUP(E6,'[11]SAP Input-BS'!$A$5:$E$500,5,0),0) -> 2.3140636e+09 | L6: 3.3323581e+09
A7: Current Assets | B7: Trade receivables | C7: Trade receivables | D7: Trade receivables - K | E7: 18020 | F7: =IFERROR(VLOOKUP(E7,'[9]SAP Input-BS'!$A$5:$F$502,5,0),0) -> 1.2685401e+10 | G7: =IFERROR(VLOOKUP(E7,'[10]SAP Input-BS'!$A$5:$F$500,5,0),0) -> 2.1422072e+10 | H7: =F7-G7 -> -8.7366717e+09 | J7: page A.1_K | K7: =IFERROR(VLOOKUP(E7,'[11]SAP Input-BS'!$A$5:$E$500,5,0),0) -> 1.6272224e+10 | L7: 1.5384514e+10
A8: Current Assets | B8: Trade receivables | C8: Trade receivables | D8: License receivables - K | E8: 18025 | F8: =IFERROR(VLOOKUP(E8,'[9]SAP Input-BS'!$A$5:$F$502,5,0),0) -> 0 | G8: =IFERROR(VLOOKUP(E8,'[10]SAP Input-BS'!$A$5:$F$500,5,0),0) -> 0 | H8: =F8-G8 -> 0 | K8: =IFERROR(VLOOKUP(E8,'[11]SAP Input-BS'!$A$5:$E$500,5,0),0) -> 0 | L8: 0
A9: Current Assets | B9: Trade receivables | C9: Trade receivables | D9: Trade receivables - N | E9: 18040 | F9: =IFERROR(VLOOKUP(E9,'[9]SAP Input-BS'!$A$5:$F$502,5,0),0) -> 2.0906083e+08 | G9: =IFERROR(VLOOKUP(E9,'[10]SAP Input-BS'!$A$5:$F$500,5,0),0) -> 2.6702677e+08 | H9: =F9-G9 -> -57965942 | J9: page A.1_N | K9: =IFERROR(VLOOKUP(E9,'[11]SAP Input-BS'!$A$5:$E$500,5,0),0) -> 1.0666313e+08 | L9: 2.5850201e+08
A10: Current Assets | B10: Trade receivables | C10: Trade receivables | D10: Trade receivables - B-a | E10: 18060 | F10: =IFERROR(VLOOKUP(E10,'[9]SAP Input-BS'!$A$5:$F$502,5,0),0) -> 0 | G10: =IFERROR(VLOOKUP(E10,'[10]SAP Input-BS'!$A$5:$F$500,5,0),0) -> 0 | H10: =F10-G10 -> 0 | K10: =IFERROR(VLOOKUP(E10,'[11]SAP Input-BS'!$A$5:$E$500,5,0),0) -> 0 | L10: 0
A11: Current Assets | B11: Trade receivables | C11: Trade receivables | D11: Total: Trade receivables | E11: AC_AR | F11: =IFERROR(VLOOKUP(E11,'[9]SAP Input-BS'!$A$5:$F$502,5,0),0) -> 1.4565878e+10 | G11: =IFERROR(VLOOKUP(E11,'[10]SAP Input-BS'!$A$5:$F$500,5,0),0) -> 2.3799634e+10 | H11: =F11-G11 -> -9.2337561e+09 | K11: =IFERROR(VLOOKUP(E11,'[11]SAP Input-BS'!$A$5:$E$500,5,0),0) -> 1.8692951e+10 | L11: 1.8975374e+10
A12: Current Assets | B12: Other current financial assets | C12: Marketable securities ≤ 1 y. | D12: Money market funds - FVPL | E12: 17057 | F12: =IFERROR(VLOOKUP(E12,'[9]SAP Input-BS'!$A$5:$F$502,5,0),0) -> 11608765263 | G12: =IFERROR(VLOOKUP(E12,'[10]SAP Input-BS'!$A$5:$F$500,5,0),0) -> 14517034946 | H12: =F12-G12 -> -2908269683 | K12: =IFERROR(VLOOKUP(E12,'[11]SAP Input-BS'!$A$5:$E$500,5,0),0) -> 11601775417 | L12: 1.1390965e+10
A13: Current Assets | B13: Other current financial assets | C13: Marketable securities ≤ 1 y. | D13: Marketable securities ≤ 1 y - FVOCI wR | E13: 17066 | F13: =IFERROR(VLOOKUP(E13,'[9]SAP Input-BS'!$A$5:$F$502,5,0),0) -> 0.08 | G13: =IFERROR(VLOOKUP(E13,'[10]SAP Input-BS'!$A$5:$F$500,5,0),0) -> 0.04 | H13: =F13-G13 -> 0.04 | K13: =IFERROR(VLOOKUP(E13,'[11]SAP Input-BS'!$A$5:$E$500,5,0),0) -> -0.34 | L13: 0
A14: Current Assets | B14: Other current financial assets | C14: Marketable securities ≤ 1 y. | D14: Marketable securities ≤ 1 y - AC | E14: 17067 | F14: =IFERROR(VLOOKUP(E14,'[9]SAP Input-BS'!$A$5:$F$502,5,0),0) -> 0 | G14: =IFERROR(VLOOKUP(E14,'[10]SAP Input-BS'!$A$5:$F$500,5,0),0) -> 0 | H14: =F14-G14 -> 0 | K14: =IFERROR(VLOOKUP(E14,'[11]SAP Input-BS'!$A$5:$E$500,5,0),0) -> 0 | L14: 0
A15: Current Assets | B15: Other current financial assets | C15: Marketable securities ≤ 1 y. | D15: Other marketable securities ≤ 1 y - FVPL | E15: 17068 | F15: =IFERROR(VLOOKUP(E15,'[9]SAP Input-BS'!$A$5:$F$502,5,0),0) -> 0 | G15: =IFERROR(VLOOKUP(E15,'[10]SAP Input-BS'!$A$5:$F$500,5,0),0) -> 0 | H15: =F15-G15 -> 0 | K15: =IFERROR(VLOOKUP(E15,'[11]SAP Input-BS'!$A$5:$E$500,5,0),0) -> 0 | L15: 0
A16: Current Assets | B16: Other current financial assets | C16: Marketable securities ≤ 1 y. | D16: Total: Marketable securities ≤ 1 y. | E16: 17099 | F16: =IFERROR(VLOOKUP(E16,'[9]SAP Input-BS'!$A$5:$F$502,5,0),0) -> 1.1608765e+10 | G16: =IFERROR(VLOOKUP(E16,'[10]SAP Input-BS'!$A$5:$F$500,5,0),0) -> 1.4517035e+10 | H16: =F16-G16 -> -2.9082697e+09 | K16: =IFERROR(VLOOKUP(E16,'[11]SAP Input-BS'!$A$5:$E$500,5,0),0) -> 1.1601775e+10 | L16: 1.1390965e+10
A17: Current Assets | B17: Other current financial assets | C17: Loans | D17: Loans ≤ 1 y - 3rd, B-c, B-f | E17: 18210 | F17: =IFERROR(VLOOKUP(E17,'[9]SAP Input-BS'!$A$5:$F$502,5,0),0) -> 0 | G17: =IFERROR(VLOOKUP(E17,'[10]SAP Input-BS'!$A$5:$F$500,5,0),0) -> 0 | H17: =F17-G17 -> 0 | K17: =IFERROR(VLOOKUP(E17,'[11]SAP Input-BS'!$A$5:$E$500,5,0),0) -> 0 | L17: 0
A18: Current Assets | B18: Other current financial assets | C18: Loans | D18: Loans ≤ 1 y - employees | E18: 18215 | F18: =IFERROR(VLOOKUP(E18,'[9]SAP Input-BS'!$A$5:$F$502,5,0),0) -> 13515405 | G18: =IFERROR(VLOOKUP(E18,'[10]SAP Input-BS'!$A$5:$F$500,5,0),0) -> 12718628 | H18: =F18-G18 -> 796777.64 | K18: =IFERROR(VLOOKUP(E18,'[11]SAP Input-BS'!$A$5:$E$500,5,0),0) -> 11675401 | L18: 12537938
A19: Current Assets | B19: Other current financial assets | C19: Loans | D19: Loans ≤ 1 y - K | E19: 18220 | F19: =IFERROR(VLOOKUP(E19,'[9]SAP Input-BS'!$A$5:$F$502,5,0),0) -> 6147292000 | G19: =IFERROR(VLOOKUP(E19,'[10]SAP Input-BS'!$A$5:$F$500,5,0),0) -> 5218076388 | H19: =F19-G19 -> 929215612 | J19: ETAS,RBAI and MPIN | K19: =IFERROR(VLOOKUP(E19,'[11]SAP Input-BS'!$A$5:$E$500,5,0),0) -> 1813902000 | L19: 5263902000
A20: Current Assets | B20: Other current financial assets | C20: Loans | D20: Loans ≤ 1 y - N | E20: 18240 | F20: =IFERROR(VLOOKUP(E20,'[9]SAP Input-BS'!$A$5:$F$502,5,0),0) -> 0 | G20: =IFERROR(VLOOKUP(E20,'[10]SAP Input-BS'!$A$5:$F$500,5,0),0) -> 0 | H20: =F20-G20 -> 0 | K20: =IFERROR(VLOOKUP(E20,'[11]SAP Input-BS'!$A$5:$E$500,5,0),0) -> 0 | L20: 0
A21: Current Assets | B21: Other current financial assets | C21: Loans | D21: Loans ≤ 1 y - B-a | E21: 18260 | F21: =IFERROR(VLOOKUP(E21,'[9]SAP Input-BS'!$A$5:$F$502,5,0),0) -> 0 | G21: =IFERROR(VLOOKUP(E21,'[10]SAP Input-BS'!$A$5:$F$500,5,0),0) -> 0 | H21: =F21-G21 -> 0 | K21: =IFERROR(VLOOKUP(E21,'[11]SAP Input-BS'!$A$5:$E$500,5,0),0) -> 0 | L21: 0
A22: Current Assets | B22: Other current financial assets | C22: Loans | D22: Loans FVPL (not SPPI compliant) ≤ 1 y - 3rd, B-c, B-f | E22: 18280 | F22: =IFERROR(VLOOKUP(E22,'[9]SAP Input-BS'!$A$5:$F$502,5,0),0) -> 0 | G22: =IFERROR(VLOOKUP(E22,'[10]SAP Input-BS'!$A$5:$F$500,5,0),0) -> 0 | H22: =F22-G22 -> 0 | K22: =IFERROR(VLOOKUP(E22,'[11]SAP Input-BS'!$A$5:$E$500,5,0),0) -> 0 | L22: 0
A23: Current Assets | B23: Other current financial assets | C23: Loans | D23: Total: Loans ≤ 1 y | E23: 18299 | F23: =IFERROR(VLOOKUP(E23,'[9]SAP Input-BS'!$A$5:$F$502,5,0),0) -> 6.1608074e+09 | G23: =IFERROR(VLOOKUP(E23,'[10]SAP Input-BS'!$A$5:$F$500,5,0),0) -> 5.230795e+09 | H23: =F23-G23 -> 9.3001239e+08 | K23: =IFERROR(VLOOKUP(E23,'[11]SAP Input-BS'!$A$5:$E$500,5,0),0) -> 1.8255774e+09 | L23: 5.2764399e+09
A24: Current Assets | B24: Other current financial assets | C24: Financial clearing, cash pool | D24: Financial clearing, cash pool - K | E24: 18320 | F24: =IFERROR(VLOOKUP(E24,'[9]SAP Input-BS'!$A$5:$F$502,5,0),0) -> 0 | G24: =IFERROR(VLOOKUP(E24,'[10]SAP Input-BS'!$A$5:$F$500,5,0),0) -> 0 | H24: =F24-G24 -> 0 | K24: =IFERROR(VLOOKUP(E24,'[11]SAP Input-BS'!$A$5:$E$500,5,0),0) -> 0 | L24: 0
A25: Current Assets | B25: Other current financial assets | C25: Financial clearing, cash pool | D25: Financial clearing, cash pool - N | E25: 18340 | F25: =IFERROR(VLOOKUP(E25,'[9]SAP Input-BS'!$A$5:$F$502,5,0),0) -> 0 | G25: =IFERROR(VLOOKUP(E25,'[10]SAP Input-BS'!$A$5:$F$500,5,0),0) -> 0 | H25: =F25-G25 -> 0 | K25: =IFERROR(VLOOKUP(E25,'[11]SAP Input-BS'!$A$5:$E$500,5,0),0) -> 0 | L25: 0
A26: Current Assets | B26: Other current financial assets | C26: Financial clearing, cash pool | D26: Finanzclearing, cash pool - B-a | E26: 18360 | F26: =IFERROR(VLOOKUP(E26,'[9]SAP Input-BS'!$A$5:$F$502,5,0),0) -> 0 | G26: =IFERROR(VLOOKUP(E26,'[10]SAP Input-BS'!$A$5:$F$500,5,0),0) -> 0 | H26: =F26-G26 -> 0 | K26: =IFERROR(VLOOKUP(E26,'[11]SAP Input-BS'!$A$5:$E$500,5,0),0) -> 0 | L26: 0
A27: Current Assets | B27: Other current financial assets | C27: Financial clearing, cash pool | D27: Finanzclearing, cash pool - B-c, B-f | E27: 18370 | F27: =IFERROR(VLOOKUP(E27,'[9]SAP Input-BS'!$A$5:$F$502,5,0),0) -> 0 | G27: =IFERROR(VLOOKUP(E27,'[10]SAP Input-BS'!$A$5:$F$500,5,0),0) -> 0 | H27: =F27-G27 -> 0 | K27: =IFERROR(VLOOKUP(E27,'[11]SAP Input-BS'!$A$5:$E$500,5,0),0) -> 0 | L27: 0
A28: Current Assets | B28: Other current financial assets | C28: Financial clearing, cash pool | D28: Total: Financial clearing, cash pool | E28: 18399 | F28: =IFERROR(VLOOKUP(E28,'[9]SAP Input-BS'!$A$5:$F$502,5,0),0) -> 0 | G28: =IFERROR(VLOOKUP(E28,'[10]SAP Input-BS'!$A$5:$F$500,5,0),0) -> 0 | H28: =F28-G28 -> 0 | K28: =IFERROR(VLOOKUP(E28,'[11]SAP Input-BS'!$A$5:$E$500,5,0),0) -> 0 | L28: 0
A29: Current Assets | B29: Other current financial assets | C29: Lease Receivables | D29: Receivables f. fin. lease (lessor) ≤ 1 y | E29: 18600 | F29: =IFERROR(VLOOKUP(E29,'[9]SAP Input-BS'!$A$5:$F$502,5,0),0) -> 3.9596487e+08 | G29: =IFERROR(VLOOKUP(E29,'[10]SAP Input-BS'!$A$5:$F$500,5,0),0) -> 3.9596487e+08 | H29: =F29-G29 -> 0 | K29: =IFERROR(VLOOKUP(E29,'[11]SAP Input-BS'!$A$5:$E$500,5,0),0) -> 6.62 | L29: 3.8461862e+08
A30: Current Assets | B30: Other current financial assets | C30: Derivative Assets | D30: Derivatives w/o hedge ≤ 1 y - 3rd | E30: 18603 | F30: =IFERROR(VLOOKUP(E30,'[9]SAP Input-BS'!$A$5:$F$502,5,0),0) -> 0 | G30: =IFERROR(VLOOKUP(E30,'[10]SAP Input-BS'!$A$5:$F$500,5,0),0) -> 0 | H30: =F30-G30 -> 0 | K30: =IFERROR(VLOOKUP(E30,'[11]SAP Input-BS'!$A$5:$E$500,5,0),0) -> 252393768 | L30: 0
A31: Current Assets | B31: Other current financial assets | C31: Travel Advances | D31: Fin. receivables board members, employees ≤ 1 y | E31: 18516 | F31: =IFERROR(VLOOKUP(E31,'[9]SAP Input-BS'!$A$5:$F$502,5,0),0) -> 5.7511126e+08 | G31: =IFERROR(VLOOKUP(E31,'[10]SAP Input-BS'!$A$5:$F$500,5,0),0) -> 1.8241202e+08 | H31: =F31-G31 -> 3.9269923e+08 | K31: =IFERROR(VLOOKUP(E31,'[11]SAP Input-BS'!$A$5:$E$500,5,0),0) -> 2.3600357e+08 | L31: 2.307519e+08
... A34: Current Assets | B34: Other current financial assets | C34: Accrued Interest (3rd party) | D34: Receivables accrued interest - 3rd, B-c, B-f | E34: 18615 | F34: =IFERROR(VLOOKUP(E34,'[9]SAP Input-BS'!$A$5:$F$502,5,0),0) -> 0 | G34: =IFERROR(VLOOKUP(E34,'[10]SAP Input-BS'!$A$5:$F$500,5,0),0) -> 0 | H34: =F34-G34 -> 0 | K34: =IFERROR(VLOOKUP(E34,'[11]SAP Input-BS'!$A$5:$E$500,5,0),0) -> 0 | L34: 0
A35: Current Assets | B35: Other current financial assets | C35: Deposits Receivable | D35: Other financial receivables ≤ 1 year third parties, B-c, B-f | E35: 18616 | F35: =IFERROR(VLOOKUP(E35,'[9]SAP Input-BS'!$A$5:$F$502,5,0),0) -> 5.3267149e+08 | G35: =IFERROR(VLOOKUP(E35,'[10]SAP Input-BS'!$A$5:$F$500,5,0),0) -> 2.762204e+08 | H35: =F35-G35 -> 256451092 | J35: Deposits, Escrow receipt | K35: =IFERROR(VLOOKUP(E35,'[11]SAP Input-BS'!$A$5:$E$500,5,0),0) -> 2.1089857e+08 | L35: 9.0024995e+09
A36: Current Assets | B36: Other current financial assets | C36: Dividend Receivables (ICR) | D36: Receivables PTA/dividends - K | E36: 18621 | F36: =IFERROR(VLOOKUP(E36,'[9]SAP Input-BS'!$A$5:$F$502,5,0),0) -> 0 | G36: =IFERROR(VLOOKUP(E36,'[10]SAP Input-BS'!$A$5:$F$500,5,0),0) -> 0 | H36: =F36-G36 -> 0 | K36: =IFERROR(VLOOKUP(E36,'[11]SAP Input-BS'!$A$5:$E$500,5,0),0) -> 0 | L36: 0
A37: Current Assets | B37: Other current financial assets | C37: Debit Balances - Creditors (ICR) | D37: Creditors with debit balances - K | E37: 18624 | F37: =IFERROR(VLOOKUP(E37,'[9]SAP Input-BS'!$A$5:$F$502,5,0),0) -> 58775 | G37: =IFERROR(VLOOKUP(E37,'[10]SAP Input-BS'!$A$5:$F$500,5,0),0) -> 46786 | H37: =F37-G37 -> 11989 | K37: =IFERROR(VLOOKUP(E37,'[11]SAP Input-BS'!$A$5:$E$500,5,0),0) -> 11142113 | L37: 21800085
A38: Current Assets | B38: Other current financial assets | C38: Accrued Interest (ICR) | D38: Receivables accrued interest - K | E38: 18625 | F38: =IFERROR(VLOOKUP(E38,'[9]SAP Input-BS'!$A$5:$F$502,5,0),0) -> 1721239.4 | G38: =IFERROR(VLOOKUP(E38,'[10]SAP Input-BS'!$A$5:$F$500,5,0),0) -> 1284707.1 | H38: =F38-G38 -> 436532.31 | K38: =IFERROR(VLOOKUP(E38,'[11]SAP Input-BS'!$A$5:$E$500,5,0),0) -> 119086.89 | L38: 462724.78
A39: Current Assets | B39: Other current financial assets | D39: Other financial receivables ≤ 1 y - K | E39: 18626 | F39: =IFERROR(VLOOKUP(E39,'[9]SAP Input-BS'!$A$5:$F$502,5,0),0) -> 0 | G39: =IFERROR(VLOOKUP(E39,'[10]SAP Input-BS'!$A$5:$F$500,5,0),0) -> 0 | H39: =F39-G39 -> 0 | K39: =IFERROR(VLOOKUP(E39,'[11]SAP Input-BS'!$A$5:$E$500,5,0),0) -> 0 | L39: 0
A40: Current Assets | B40: Other current financial assets | D40: Receivables PTA/dividends - N | E40: 18641 | F40: =IFERROR(VLOOKUP(E40,'[9]SAP Input-BS'!$A$5:$F$502,5,0),0) -> 0 | G40: =IFERROR(VLOOKUP(E40,'[10]SAP Input-BS'!$A$5:$F$500,5,0),0) -> 0 | H40: =F40-G40 -> 0 | K40: =IFERROR(VLOOKUP(E40,'[11]SAP Input-BS'!$A$5:$E$500,5,0),0) -> 0 | L40: 0
A41: Current Assets | B41: Other current financial assets | C41: Debit Balances - Creditors (3rd Party) | D41: Creditors with debit balances - N | E41: 18644 | F41: =IFERROR(VLOOKUP(E41,'[9]SAP Input-BS'!$A$5:$F$502,5,0),0) -> 0 | G41: =IFERROR(VLOOKUP(E41,'[10]SAP Input-BS'!$A$5:$F$500,5,0),0) -> 2100157 | H41: =F41-G41 -> -2100157 | K41: =IFERROR(VLOOKUP(E41,'[11]SAP Input-BS'!$A$5:$E$500,5,0),0) -> 1731827.8 | L41: 1731827.8
A42: Current Assets | B42: Other current financial assets | D42: Receivables accrued interest - N | E42: 18645 | F42: =IFERROR(VLOOKUP(E42,'[9]SAP Input-BS'!$A$5:$F$502,5,0),0) -> 0 | G42: =IFERROR(VLOOKUP(E42,'[10]SAP Input-BS'!$A$5:$F$500,5,0),0) -> 0 | H42: =F42-G42 -> 0 | K42: =IFERROR(VLOOKUP(E42,'[11]SAP Input-BS'!$A$5:$E$500,5,0),0) -> 0 | L42: 0
...

Sheet Sheet2
A2: Assets | B2: Why has cash reduced so much | G2: ='BS-Assets'!G4 -> 1560768050 | H2: =G2/87/10^6 -> 17.939863 | J2: =#REF! -> #REF! | K2: =H2-J2 -> #REF!
B3: SDS Invesmtnet | G3: =-10*10^7 -> -100000000 | H3: =G3/87/10^6 -> -1.1494253 | K3: =H3 -> -1.1494253
B4: AI Shield Investment | G4: =-33*10^7 -> -330000000 | H4: =G4/87/10^6 -> -3.7931034 | K4: =H4 -> -3.7931034
B5: Advance Tax Payent | G5: =-3220*10^6 -> -3220000000 | H5: =G5/87/10^6 -> -37.011494 | K5: =H5 -> -37.011494
B6: Excess payments vs Lower collection | K6: -93
B7: Escrow relevae Johnson Controls | K7: =[13]Cashflow_2026_Collection_wise!$D$16/87 -> 100.49446
B8: Bonus Payouts | K8: -40.229885
K9: =SUM(K2:K8) -> #REF!
B10: Trade receivables break up | G10: =SUM(G2:G6) -> -2089231950
B11: ICR | G11: ='BS-Assets'!F4 -> 1.2020967e+10
B12: SDS | G12: =G10-G11 -> -1.4110199e+10
B14: Marketable securities - Schedule
B15: MTM (FVTPL done in March'26 and Mar'25)
B17: Fin. receivables board members, employees ≤ 1 y
B18: Other financial receivables ≤ 1 year third parties, B-c, B-f
B20: Other financial receivables ≤ 1 y - B-a
B21: How its so low and negative sign in Assets
B23: Total: Investments (wo B-a)
B24: SDS and AI shield
B26: Contract assets (CA) > 1 y | D26: CA: Sales over time > 1 y - 3rd, N, B-a, B-c, B-f
B28: CWIP ageing
B30: Other tax receivables > 1 year
A32: Liabilities | B32: Trade Payables - old balances Split
B34: Other financial liabilities ≤ 1 y - 3rd, B-c, B-f | C34: 21318
B36: Financial liabil. to board members, employees ≤ 1 y
B38: CL: Sales over time ≤ 1 y - 3rd, N, B-a, B-c, B-f | C38: 20200
B40: Liabil. to board members, employees ≤ 1 y | C40: 21390
B41: Liabil. to board memb., employees > 1 y
B43: Personnel related provisions > 1 y
B44: Personnel related provisions < 1 y
